Workbook

Sheet Campaign Data
A1: campaign_id | B1: campaign_name | C1: channel | D1: campaign_type | E1: start_date | F1: end_date | G1: spend | H1: impressions | I1: clicks | J1: conversions | K1: revenue | L1: ctr | M1: conversion_rate | N1: roas | O1: cpc | P1: cost_per_conversion
A2: 5000 | B2: Cart Recovery - Instagram | C2: Instagram Ads | D2: Retargeting | E2: 45658 | F2: 45701 | G2: 1954.92 | H2: 149459 | I2: 2615 | J2: 48 | K2: 3242.88 | L2: =IFERROR(I2/H2,0) -> 0.017496437 | M2: =IFERROR(J2/I2,0) -> 0.018355641 | N2: =IFERROR(K2/G2,0) -> 1.65883 | O2: =IFERROR(G2/I2,0) -> 0.74757935 | P2: =IFERROR(G2/J2,0) -> 40.7275
A3: 5001 | B3: Referral Boost - Instagram | C3: Instagram Ads | D3: Product Launch | E3: 45564 | F3: 45567 | G3: 121.67 | H3: 9403 | I3: 140 | J3: 4 | K3: 96.64 | L3: =IFERROR(I3/H3,0) -> 0.014888865 | M3: =IFERROR(J3/I3,0) -> 0.028571429 | N3: =IFERROR(K3/G3,0) -> 0.79427961 | O3: =IFERROR(G3/I3,0) -> 0.86907143 | P3: =IFERROR(G3/J3,0) -> 30.4175
A4: 5002 | B4: Cart Recovery - Email | C4: Email Marketing | D4: Lead Generation | E4: 45465 | F4: 45495 | G4: 755.21 | H4: 389285 | I4: 19786 | J4: 1596 | K4: 92791.44 | L4: =IFERROR(I4/H4,0) -> 0.050826515 | M4: =IFERROR(J4/I4,0) -> 0.080663095 | N4: =IFERROR(K4/G4,0) -> 122.86839 | O4: =IFERROR(G4/I4,0) -> 0.038168907 | P4: =IFERROR(G4/J4,0) -> 0.47318922
A5: 5003 | B5: Weekend Special - Affiliate | C5: Affiliate Marketing | D5: Brand Awareness | E5: 45632 | F5: 45636 | G5: 176.31 | H5: 83166 | I5: 3404 | J5: 86 | K5: 8060.78 | L5: =IFERROR(I5/H5,0) -> 0.040930188 | M5: =IFERROR(J5/I5,0) -> 0.025264395 | N5: =IFERROR(K5/G5,0) -> 45.719358 | O5: =IFERROR(G5/I5,0) -> 0.051794947 | P5: =IFERROR(G5/J5,0) -> 2.0501163
A6: 5004 | B6: Cart Recovery - Instagram | C6: Instagram Ads | D6: Product Launch | E6: 45619 | F6: 45647 | G6: 3380.84 | H6: 256124 | I6: 2465 | J6: 90 | K6: 4338 | L6: =IFERROR(I6/H6,0) -> 0.0096242445 | M6: =IFERROR(J6/I6,0) -> 0.036511156 | N6: =IFERROR(K6/G6,0) -> 1.2831131 | O6: =IFERROR(G6/I6,0) -> 1.3715375 | P6: =IFERROR(G6/J6,0) -> 37.564889
A7: 5005 | B7: Flash Deal - Google | C7: Google Search Ads | D7: Lead Generation | E7: 45788 | F7: 45833 | G7: 3663.07 | H7: 397728 | I7: 30608 | J7: 2840 | K7: 337931.6 | L7: =IFERROR(I7/H7,0) -> 0.076957116 | M7: =IFERROR(J7/I7,0) -> 0.0927862 | N7: =IFERROR(K7/G7,0) -> 92.253656 | O7: =IFERROR(G7/I7,0) -> 0.11967688 | P7: =IFERROR(G7/J7,0) -> 1.2898134
A8: 5006 | B8: App Install Drive - Affiliate | C8: Affiliate Marketing | D8: Product Launch | E8: 45642 | F8: 45657 | G8: 757.98 | H8: 180903 | I8: 8558 | J8: 626 | K8: 37447.32 | L8: =IFERROR(I8/H8,0) -> 0.04730712 | M8: =IFERROR(J8/I8,0) -> 0.073147932 | N8: =IFERROR(K8/G8,0) -> 49.4041 | O8: =IFERROR(G8/I8,0) -> 0.088569759 | P8: =IFERROR(G8/J8,0) -> 1.2108307
A9: 5007 | B9: Back to School - Affiliate | C9: Affiliate Marketing | D9: Product Launch | E9: 45606 | F9: 45640 | G9: 1289.52 | H9: 204686 | I9: 4973 | J9: 348 | K9: 13401.48 | L9: =IFERROR(I9/H9,0) -> 0.024295751 | M9: =IFERROR(J9/I9,0) -> 0.069977881 | N9: =IFERROR(K9/G9,0) -> 10.392611 | O9: =IFERROR(G9/I9,0) -> 0.25930424 | P9: =IFERROR(G9/J9,0) -> 3.7055172
A10: 5008 | B10: Year End Clearance - Affiliate | C10: Affiliate Marketing | D10: Brand Awareness | E10: 45479 | F10: 45517 | G10: 1688.75 | H10: 316246 | I10: 13024 | J10: 433 | K10: 33237.08 | L10: =IFERROR(I10/H10,0) -> 0.04118313 | M10: =IFERROR(J10/I10,0) -> 0.033246314 | N10: =IFERROR(K10/G10,0) -> 19.681469 | O10: =IFERROR(G10/I10,0) -> 0.12966447 | P10: =IFERROR(G10/J10,0) -> 3.9001155
A11: 5009 | B11: Weekend Special - Google | C11: Google Search Ads | D11: Lead Generation | E11: 45531 | F11: 45574 | G11: 4392.53 | H11: 184560 | I11: 12922 | J11: 688 | K11: 67816.16 | L11: =IFERROR(I11/H11,0) -> 0.070015171 | M11: =IFERROR(J11/I11,0) -> 0.053242532 | N11: =IFERROR(K11/G11,0) -> 15.438975 | O11: =IFERROR(G11/I11,0) -> 0.33992648 | P11: =IFERROR(G11/J11,0) -> 6.3844913
A12: 5010 | B12: Holiday Promo - Email | C12: Email Marketing | D12: Brand Awareness | E12: 45477 | F12: 45491 | G12: 524.01 | H12: 409381 | I12: 15207 | J12: 851 | K12: 23615.25 | L12: =IFERROR(I12/H12,0) -> 0.037146326 | M12: =IFERROR(J12/I12,0) -> 0.055961071 | N12: =IFERROR(K12/G12,0) -> 45.066411 | O12: =IFERROR(G12/I12,0) -> 0.034458473 | P12: =IFERROR(G12/J12,0) -> 0.61575793
A13: 5011 | B13: VIP Early Access - Email | C13: Email Marketing | D13: Retargeting | E13: 45527 | F13: 45567 | G13: 8.24 | H13: 9477 | I13: 524 | J13: 46 | K13: 2445.82 | L13: =IFERROR(I13/H13,0) -> 0.055291759 | M13: =IFERROR(J13/I13,0) -> 0.08778626 | N13: =IFERROR(K13/G13,0) -> 296.82282 | O13: =IFERROR(G13/I13,0) -> 0.015725191 | P13: =IFERROR(G13/J13,0) -> 0.17913043
... A501: 5499 | B501: New Customer Push - Email | C501: Email Marketing | D501: Brand Awareness | E501: 45748 | F501: 45791 | G501: 311.61 | H501: 270962 | I501: 5628 | J501: 607 | K501: 47212.46 | L501: =IFERROR(I501/H501,0) -> 0.02077044 | M501: =IFERROR(J501/I501,0) -> 0.10785359 | N501: =IFERROR(K501/G501,0) -> 151.51138 | O501: =IFERROR(G501/I501,0) -> 0.055367804 | P501: =IFERROR(G501/J501,0) -> 0.51336079

Sheet Sheet1
A3: Row Labels | B3: Sum of Revenue | D3: Row Labels | E3: Sum of ROAS | H3: Row Labels | I3: Sum of Revenue | J3: Sum of Spend
A4: Affiliate Marketing | B4: 2181109.4 | D4: Affiliate Marketing | E4: 23.067056 | H4: Affiliate Marketing | I4: 2181109.4 | J4: 94555.17
A5: Email Marketing | B5: 3453251.9 | D5: Email Marketing | E5: 170.61951 | H5: Email Marketing | I5: 3453251.9 | J5: 20239.49
A6: Facebook Ads | B6: 820762 | D6: Facebook Ads | E6: 5.3194763 | H6: Facebook Ads | I6: 820762 | J6: 154293.76
A7: Google Search Ads | B7: 4401880 | D7: Google Search Ads | E7: 15.972532 | H7: Google Search Ads | I7: 4401880 | J7: 275590.62
A8: Instagram Ads | B8: 415144.28 | D8: Instagram Ads | E8: 3.1340928 | H8: Instagram Ads | I8: 415144.28 | J8: 132460.75
A9: LinkedIn Ads | B9: 513536.53 | D9: LinkedIn Ads | E9: 1.7479998 | H9: LinkedIn Ads | I9: 513536.53 | J9: 293785.24
A10: TikTok Ads | B10: 312618.48 | D10: TikTok Ads | E10: 3.0806925 | H10: TikTok Ads | I10: 312618.48 | J10: 101476.69
A11: YouTube Ads | B11: 203135.99 | D11: YouTube Ads | E11: 1.2155952 | H11: YouTube Ads | I11: 203135.99 | J11: 167108.25
A12: Grand Total | B12: 12301439 | D12: Grand Total | E12: 224.15696 | H12: Grand Total | I12: 12301439 | J12: 1239510
A17: Row Labels | B17: Sum of Revenue
A18: Affiliate Marketing | B18: 2181109.4
A19: Email Marketing | B19: 3453251.9
A20: Facebook Ads | B20: 820762
A21: Google Search Ads | B21: 4401880
A22: Instagram Ads | B22: 415144.28
A23: LinkedIn Ads | B23: 513536.53
A24: TikTok Ads | B24: 312618.48
A25: YouTube Ads | B25: 203135.99
A26: Grand Total | B26: 12301439
A28: Row Labels | B28: Sum of Revenue | D28: Row Labels | E28: Sum of ROAS | H28: Row Labels | I28: Sum of Spend | J28: Sum of Revenue
A29: Brand Awareness | B29: 2816303.9 | D29: Brand Awareness | E29: 11.37564 | H29: Brand Awareness | I29: 247573.23 | J29: 2816303.9
A30: Conversion | B30: 2200752.6 | D30: Conversion | E30: 8.3808893 | H30: Conversion | I30: 262591.78 | J30: 2200752.6
A31: Lead Generation | B31: 3676561.7 | D31: Lead Generation | E31: 13.455498 | H31: Lead Generation | I31: 273238.63 | J31: 3676561.7
A32: Product Launch | B32: 2131726 | D32: Product Launch | E32: 8.7984163 | H32: Product Launch | I32: 242285.19 | J32: 2131726
A33: Retargeting | B33: 1476094.3 | D33: Retargeting | E33: 6.9034069 | H33: Retargeting | I33: 213821.14 | J33: 1476094.3
A34: Grand Total | B34: 12301439 | D34: Grand Total | E34: 48.91385 | H34: Grand Total | I34: 1239510 | J34: 12301439

Sheet Pivot Tables
A1: Marketing Campaign Analysis — Pivot Tables
A3: Total Campaigns | B3: =COUNTA('Campaign Data'!A2:A501) -> 500
A4: Total Spend | B4: =SUM('Campaign Data'!G2:G501) -> 1239510
A5: Total Revenue | B5: =SUM('Campaign Data'!K2:K501) -> 12301439
A6: Total Impressions | B6: =SUM('Campaign Data'!H2:H501) -> 125564569
A7: Total Clicks | B7: =SUM('Campaign Data'!I2:I501) -> 3547356
A8: Total Conversions | B8: =SUM('Campaign Data'!J2:J501) -> 183272
A9: Overall CTR | B9: =IFERROR(SUM('Campaign Data'!I2:I501)/SUM('Campaign Data'!H2:H501),0) -> 0.02825125
A10: Overall Conversion Rate | B10: =IFERROR(SUM('Campaign Data'!J2:J501)/SUM('Campaign Data'!I2:I501),0) -> 0.051664395
A11: Overall ROAS | B11: =IFERROR(SUM('Campaign Data'!K2:K501)/SUM('Campaign Data'!G2:G501),0) -> 9.924437
A15: Performance by Channel
A16: Channel | B16: Campaigns | C16: Spend | D16: Revenue | E16: Impressions | F16: Clicks | G16: Conversions | H16: ROAS
A17: Affiliate Marketing | B17: =COUNTIF('Campaign Data'!C:C,A17) -> 80 | C17: =SUMIF('Campaign Data'!C:C,A17,'Campaign Data'!G:G) -> 94555.17 | D17: =SUMIF('Campaign Data'!C:C,A17,'Campaign Data'!K:K) -> 2181109.4 | E17: =SUMIF('Campaign Data'!C:C,A17,'Campaign Data'!H:H) -> 18683368 | F17: =SUMIF('Campaign Data'!C:C,A17,'Campaign Data'!I:I) -> 637183 | G17: =SUMIF('Campaign Data'!C:C,A17,'Campaign Data'!J:J) -> 30455 | H17: =IFERROR(D17/C17,0) -> 23.067056
A18: Email Marketing | B18: =COUNTIF('Campaign Data'!C:C,A18) -> 63 | C18: =SUMIF('Campaign Data'!C:C,A18,'Campaign Data'!G:G) -> 20239.49 | D18: =SUMIF('Campaign Data'!C:C,A18,'Campaign Data'!K:K) -> 3453251.9 | E18: =SUMIF('Campaign Data'!C:C,A18,'Campaign Data'!H:H) -> 16547252 | F18: =SUMIF('Campaign Data'!C:C,A18,'Campaign Data'!I:I) -> 703577 | G18: =SUMIF('Campaign Data'!C:C,A18,'Campaign Data'!J:J) -> 60144 | H18: =IFERROR(D18/C18,0) -> 170.61951
A19: Facebook Ads | B19: =COUNTIF('Campaign Data'!C:C,A19) -> 66 | C19: =SUMIF('Campaign Data'!C:C,A19,'Campaign Data'!G:G) -> 154293.76 | D19: =SUMIF('Campaign Data'!C:C,A19,'Campaign Data'!K:K) -> 820762 | E19: =SUMIF('Campaign Data'!C:C,A19,'Campaign Data'!H:H) -> 18574031 | F19: =SUMIF('Campaign Data'!C:C,A19,'Campaign Data'!I:I) -> 407045 | G19: =SUMIF('Campaign Data'!C:C,A19,'Campaign Data'!J:J) -> 14482 | H19: =IFERROR(D19/C19,0) -> 5.3194763
A20: Google Search Ads | B20: =COUNTIF('Campaign Data'!C:C,A20) -> 60 | C20: =SUMIF('Campaign Data'!C:C,A20,'Campaign Data'!G:G) -> 275590.62 | D20: =SUMIF('Campaign Data'!C:C,A20,'Campaign Data'!K:K) -> 4401880 | E20: =SUMIF('Campaign Data'!C:C,A20,'Campaign Data'!H:H) -> 16105523 | F20: =SUMIF('Campaign Data'!C:C,A20,'Campaign Data'!I:I) -> 836174 | G20: =SUMIF('Campaign Data'!C:C,A20,'Campaign Data'!J:J) -> 54996 | H20: =IFERROR(D20/C20,0) -> 15.972532
A21: Instagram Ads | B21: =COUNTIF('Campaign Data'!C:C,A21) -> 62 | C21: =SUMIF('Campaign Data'!C:C,A21,'Campaign Data'!G:G) -> 132460.75 | D21: =SUMIF('Campaign Data'!C:C,A21,'Campaign Data'!K:K) -> 415144.28 | E21: =SUMIF('Campaign Data'!C:C,A21,'Campaign Data'!H:H) -> 13800541 | F21: =SUMIF('Campaign Data'!C:C,A21,'Campaign Data'!I:I) -> 272252 | G21: =SUMIF('Campaign Data'!C:C,A21,'Campaign Data'!J:J) -> 8548 | H21: =IFERROR(D21/C21,0) -> 3.1340928
A22: LinkedIn Ads | B22: =COUNTIF('Campaign Data'!C:C,A22) -> 51 | C22: =SUMIF('Campaign Data'!C:C,A22,'Campaign Data'!G:G) -> 293785.24 | D22: =SUMIF('Campaign Data'!C:C,A22,'Campaign Data'!K:K) -> 513536.53 | E22: =SUMIF('Campaign Data'!C:C,A22,'Campaign Data'!H:H) -> 11948779 | F22: =SUMIF('Campaign Data'!C:C,A22,'Campaign Data'!I:I) -> 115582 | G22: =SUMIF('Campaign Data'!C:C,A22,'Campaign Data'!J:J) -> 3024 | H22: =IFERROR(D22/C22,0) -> 1.7479998
A23: TikTok Ads | B23: =COUNTIF('Campaign Data'!C:C,A23) -> 62 | C23: =SUMIF('Campaign Data'!C:C,A23,'Campaign Data'!G:G) -> 101476.69 | D23: =SUMIF('Campaign Data'!C:C,A23,'Campaign Data'!K:K) -> 312618.48 | E23: =SUMIF('Campaign Data'!C:C,A23,'Campaign Data'!H:H) -> 16416668 | F23: =SUMIF('Campaign Data'!C:C,A23,'Campaign Data'!I:I) -> 409546 | G23: =SUMIF('Campaign Data'!C:C,A23,'Campaign Data'!J:J) -> 7829 | H23: =IFERROR(D23/C23,0) -> 3.0806925
A24: YouTube Ads | B24: =COUNTIF('Campaign Data'!C:C,A24) -> 56 | C24: =SUMIF('Campaign Data'!C:C,A24,'Campaign Data'!G:G) -> 167108.25 | D24: =SUMIF('Campaign Data'!C:C,A24,'Campaign Data'!K:K) -> 203135.99 | E24: =SUMIF('Campaign Data'!C:C,A24,'Campaign Data'!H:H) -> 13488407 | F24: =SUMIF('Campaign Data'!C:C,A24,'Campaign Data'!I:I) -> 165997 | G24: =SUMIF('Campaign Data'!C:C,A24,'Campaign Data'!J:J) -> 3794 | H24: =IFERROR(D24/C24,0) -> 1.2155952
A28: Performance by Campaign Type
A29: Campaign Type | B29: Campaigns | C29: Spend | D29: Revenue | E29: Impressions | F29: Clicks | G29: Conversions | H29: ROAS
A30: Brand Awareness | B30: =COUNTIF('Campaign Data'!D:D,A30) -> 111 | C30: =SUMIF('Campaign Data'!D:D,A30,'Campaign Data'!G:G) -> 247573.23 | D30: =SUMIF('Campaign Data'!D:D,A30,'Campaign Data'!K:K) -> 2816303.9 | E30: =SUMIF('Campaign Data'!D:D,A30,'Campaign Data'!H:H) -> 25557670 | F30: =SUMIF('Campaign Data'!D:D,A30,'Campaign Data'!I:I) -> 776009 | G30: =SUMIF('Campaign Data'!D:D,A30,'Campaign Data'!J:J) -> 38463 | H30: =IFERROR(D30/C30,0) -> 11.37564
A31: Conversion | B31: =COUNTIF('Campaign Data'!D:D,A31) -> 105 | C31: =SUMIF('Campaign Data'!D:D,A31,'Campaign Data'!G:G) -> 262591.78 | D31: =SUMIF('Campaign Data'!D:D,A31,'Campaign Data'!K:K) -> 2200752.6 | E31: =SUMIF('Campaign Data'!D:D,A31,'Campaign Data'!H:H) -> 27483931 | F31: =SUMIF('Campaign Data'!D:D,A31,'Campaign Data'!I:I) -> 726035 | G31: =SUMIF('Campaign Data'!D:D,A31,'Campaign Data'!J:J) -> 33456 | H31: =IFERROR(D31/C31,0) -> 8.3808893
A32: Lead Generation | B32: =COUNTIF('Campaign Data'!D:D,A32) -> 106 | C32: =SUMIF('Campaign Data'!D:D,A32,'Campaign Data'!G:G) -> 273238.63 | D32: =SUMIF('Campaign Data'!D:D,A32,'Campaign Data'!K:K) -> 3676561.7 | E32: =SUMIF('Campaign Data'!D:D,A32,'Campaign Data'!H:H) -> 27869498 | F32: =SUMIF('Campaign Data'!D:D,A32,'Campaign Data'!I:I) -> 874825 | G32: =SUMIF('Campaign Data'!D:D,A32,'Campaign Data'!J:J) -> 51331 | H32: =IFERROR(D32/C32,0) -> 13.455498
A33: Product Launch | B33: =COUNTIF('Campaign Data'!D:D,A33) -> 91 | C33: =SUMIF('Campaign Data'!D:D,A33,'Campaign Data'!G:G) -> 242285.19 | D33: =SUMIF('Campaign Data'!D:D,A33,'Campaign Data'!K:K) -> 2131726 | E33: =SUMIF('Campaign Data'!D:D,A33,'Campaign Data'!H:H) -> 23172896 | F33: =SUMIF('Campaign Data'!D:D,A33,'Campaign Data'!I:I) -> 651869 | G33: =SUMIF('Campaign Data'!D:D,A33,'Campaign Data'!J:J) -> 36903 | H33: =IFERROR(D33/C33,0) -> 8.7984163
A34: Retargeting | B34: =COUNTIF('Campaign Data'!D:D,A34) -> 87 | C34: =SUMIF('Campaign Data'!D:D,A34,'Campaign Data'!G:G) -> 213821.14 | D34: =SUMIF('Campaign Data'!D:D,A34,'Campaign Data'!K:K) -> 1476094.3 | E34: =SUMIF('Campaign Data'!D:D,A34,'Campaign Data'!H:H) -> 21480574 | F34: =SUMIF('Campaign Data'!D:D,A34,'Campaign Data'!I:I) -> 518618 | G34: =SUMIF('Campaign Data'!D:D,A34,'Campaign Data'!J:J) -> 23119 | H34: =IFERROR(D34/C34,0) -> 6.9034069
A38: Top Campaigns by Revenue
A39: Campaign | B39: Channel | C39: Type | D39: Spend | E39: Revenue | F39: Conversions | G39: ROAS
A40: ='Campaign Data'!B7 -> Flash Deal - Google | B40: ='Campaign Data'!C7 -> Google Search Ads | C40: ='Campaign Data'!D7 -> Lead Generation | D40: ='Campaign Data'!G7 -> 3663.07 | E40: ='Campaign Data'!K7 -> 337931.6 | F40: ='Campaign Data'!J7 -> 2840 | G40: ='Campaign Data'!N7 -> 92.253656
A41: ='Campaign Data'!B486 -> Brand Refresh - Google | B41: ='Campaign Data'!C486 -> Google Search Ads | C41: ='Campaign Data'!D486 -> Lead Generation | D41: ='Campaign Data'!G486 -> 6239.5 | E41: ='Campaign Data'!K486 -> 260831.67 | F41: ='Campaign Data'!J486 -> 2761 | G41: ='Campaign Data'!N486 -> 41.803297
A42: ='Campaign Data'!B88 -> Product Launch - Email | B42: ='Campaign Data'!C88 -> Email Marketing | C42: ='Campaign Data'!D88 -> Conversion | D42: ='Campaign Data'!G88 -> 272.54 | E42: ='Campaign Data'!K88 -> 205182.6 | F42: ='Campaign Data'!J88 -> 2058 | G42: ='Campaign Data'!N88 -> 752.85316
A43: ='Campaign Data'!B244 -> New Customer Push - Email | B43: ='Campaign Data'!C244 -> Email Marketing | C43: ='Campaign Data'!D244 -> Lead Generation | D43: ='Campaign Data'!G244 -> 655.81 | E43: ='Campaign Data'!K244 -> 180436.41 | F43: ='Campaign Data'!J244 -> 2541 | G43: ='Campaign Data'!N244 -> 275.13519
A44: ='Campaign Data'!B67 -> Flash Deal - Google | B44: ='Campaign Data'!C67 -> Google Search Ads | C44: ='Campaign Data'!D67 -> Lead Generation | D44: ='Campaign Data'!G67 -> 3385.94 | E44: ='Campaign Data'!K67 -> 171006.32 | F44: ='Campaign Data'!J67 -> 1906 | G44: ='Campaign Data'!N67 -> 50.504829
A45: ='Campaign Data'!B367 -> Brand Refresh - Google | B45: ='Campaign Data'!C367 -> Google Search Ads | C45: ='Campaign Data'!D367 -> Conversion | D45: ='Campaign Data'!G367 -> 9446.03 | E45: ='Campaign Data'!K367 -> 169392.24 | F45: ='Campaign Data'!J367 -> 2316 | G45: ='Campaign Data'!N367 -> 17.932638
A46: ='Campaign Data'!B176 -> VIP Early Access - Google | B46: ='Campaign Data'!C176 -> Google Search Ads | C46: ='Campaign Data'!D176 -> Brand Awareness | D46: ='Campaign Data'!G176 -> 5835.7 | E46: ='Campaign Data'!K176 -> 165859.26 | F46: ='Campaign Data'!J176 -> 2226 | G46: ='Campaign Data'!N176 -> 28.421485
A47: ='Campaign Data'!B381 -> Weekend Special - Email | B47: ='Campaign Data'!C381 -> Email Marketing | C47: ='Campaign Data'!D381 -> Retargeting | D47: ='Campaign Data'!G381 -> 277.65 | E47: ='Campaign Data'!K381 -> 160588.09 | F47: ='Campaign Data'!J381 -> 1807 | G47: ='Campaign Data'!N381 -> 578.38318
A48: ='Campaign Data'!B218 -> App Install Drive - Email | B48: ='Campaign Data'!C218 -> Email Marketing | C48: ='Campaign Data'!D218 -> Product Launch | D48: ='Campaign Data'!G218 -> 655.24 | E48: ='Campaign Data'!K218 -> 148851.6 | F48: ='Campaign Data'!J218 -> 3260 | G48: ='Campaign Data'!N218 -> 227.17111
A49: ='Campaign Data'!B249 -> VIP Early Access - Google | B49: ='Campaign Data'!C249 -> Google Search Ads | C49: ='Campaign Data'!D249 -> Conversion | D49: ='Campaign Data'!G249 -> 4472.56 | E49: ='Campaign Data'!K249 -> 144384.24 | F49: ='Campaign Data'!J249 -> 2404 | G49: ='Campaign Data'!N249 -> 32.282237
A50: ='Campaign Data'!B256 -> VIP Early Access - Google | B50: ='Campaign Data'!C256 -> Google Search Ads | C50: ='Campaign Data'!D256 -> Product Launch | D50: ='Campaign Data'!G256 -> 7048.31 | E50: ='Campaign Data'!K256 -> 142615.18 | F50: ='Campaign Data'!J256 -> 1594 | G50: ='Campaign Data'!N256 -> 20.233954
...

Sheet Dashboard
A1: MARKETING CAMPAIGN PERFORMANCE DASHBOARD
A4: Total Campaigns | D4: Total Spend | G4: Total Revenue | J4: Overall ROAS
A5: ='Pivot Tables'!B3 -> 500 | D5: ='Pivot Tables'!B4 -> 1239510 | G5: ='Pivot Tables'!B5 -> 12301439 | J5: ='Pivot Tables'!B11 -> 9.924437
A8: Impressions | D8: Clicks | G8: Conversions | J8: Conversion Rate
A9: ='Pivot Tables'!B6 -> 125564569 | D9: ='Pivot Tables'!B7 -> 3547356 | G9: ='Pivot Tables'!B8 -> 183272 | J9: ='Pivot Tables'!B10 -> 0.051664395
D12: channel analysis
D27: campaign type analysis
A47: TOP CAMPAIGNS BY REVENUE
A48: Campaign | B48: Channel | C48: Type | D48: Spend | E48: Revenue | F48: Conversions | G48: ROAS
A49: ='Pivot Tables'!A40 -> Flash Deal - Google | B49: ='Pivot Tables'!B40 -> Google Search Ads | C49: ='Pivot Tables'!C40 -> Lead Generation | D49: ='Pivot Tables'!D40 -> 3663.07 | E49: ='Pivot Tables'!E40 -> 337931.6 | F49: ='Pivot Tables'!F40 -> 2840 | G49: ='Pivot Tables'!G40 -> 92.253656
A50: ='Pivot Tables'!A41 -> Brand Refresh - Google | B50: ='Pivot Tables'!B41 -> Google Search Ads | C50: ='Pivot Tables'!C41 -> Lead Generation | D50: ='Pivot Tables'!D41 -> 6239.5 | E50: ='Pivot Tables'!E41 -> 260831.67 | F50: ='Pivot Tables'!F41 -> 2761 | G50: ='Pivot Tables'!G41 -> 41.803297
A51: ='Pivot Tables'!A42 -> Product Launch - Email | B51: ='Pivot Tables'!B42 -> Email Marketing | C51: ='Pivot Tables'!C42 -> Conversion | D51: ='Pivot Tables'!D42 -> 272.54 | E51: ='Pivot Tables'!E42 -> 205182.6 | F51: ='Pivot Tables'!F42 -> 2058 | G51: ='Pivot Tables'!G42 -> 752.85316
A52: ='Pivot Tables'!A43 -> New Customer Push - Email | B52: ='Pivot Tables'!B43 -> Email Marketing | C52: ='Pivot Tables'!C43 -> Lead Generation | D52: ='Pivot Tables'!D43 -> 655.81 | E52: ='Pivot Tables'!E43 -> 180436.41 | F52: ='Pivot Tables'!F43 -> 2541 | G52: ='Pivot Tables'!G43 -> 275.13519
A53: ='Pivot Tables'!A44 -> Flash Deal - Google | B53: ='Pivot Tables'!B44 -> Google Search Ads | C53: ='Pivot Tables'!C44 -> Lead Generation | D53: ='Pivot Tables'!D44 -> 3385.94 | E53: ='Pivot Tables'!E44 -> 171006.32 | F53: ='Pivot Tables'!F44 -> 1906 | G53: ='Pivot Tables'!G44 -> 50.504829
A54: ='Pivot Tables'!A45 -> Brand Refresh - Google | B54: ='Pivot Tables'!B45 -> Google Search Ads | C54: ='Pivot Tables'!C45 -> Conversion | D54: ='Pivot Tables'!D45 -> 9446.03 | E54: ='Pivot Tables'!E45 -> 169392.24 | F54: ='Pivot Tables'!F45 -> 2316 | G54: ='Pivot Tables'!G45 -> 17.932638
A55: ='Pivot Tables'!A46 -> VIP Early Access - Google | B55: ='Pivot Tables'!B46 -> Google Search Ads | C55: ='Pivot Tables'!C46 -> Brand Awareness | D55: ='Pivot Tables'!D46 -> 5835.7 | E55: ='Pivot Tables'!E46 -> 165859.26 | F55: ='Pivot Tables'!F46 -> 2226 | G55: ='Pivot Tables'!G46 -> 28.421485
A56: ='Pivot Tables'!A47 -> Weekend Special - Email | B56: ='Pivot Tables'!B47 -> Email Marketing | C56: ='Pivot Tables'!C47 -> Retargeting | D56: ='Pivot Tables'!D47 -> 277.65 | E56: ='Pivot Tables'!E47 -> 160588.09 | F56: ='Pivot Tables'!F47 -> 1807 | G56: ='Pivot Tables'!G47 -> 578.38318
A57: ='Pivot Tables'!A48 -> App Install Drive - Email | B57: ='Pivot Tables'!B48 -> Email Marketing | C57: ='Pivot Tables'!C48 -> Product Launch | D57: ='Pivot Tables'!D48 -> 655.24 | E57: ='Pivot Tables'!E48 -> 148851.6 | F57: ='Pivot Tables'!F48 -> 3260 | G57: ='Pivot Tables'!G48 -> 227.17111
A58: ='Pivot Tables'!A49 -> VIP Early Access - Google | B58: ='Pivot Tables'!B49 -> Google Search Ads | C58: ='Pivot Tables'!C49 -> Conversion | D58: ='Pivot Tables'!D49 -> 4472.56 | E58: ='Pivot Tables'!E49 -> 144384.24 | F58: ='Pivot Tables'!F49 -> 2404 | G58: ='Pivot Tables'!G49 -> 32.282237
A59: ='Pivot Tables'!A50 -> VIP Early Access - Google | B59: ='Pivot Tables'!B50 -> Google Search Ads | C59: ='Pivot Tables'!C50 -> Product Launch | D59: ='Pivot Tables'!D50 -> 7048.31 | E59: ='Pivot Tables'!E50 -> 142615.18 | F59: ='Pivot Tables'!F50 -> 1594 | G59: ='Pivot Tables'!G50 -> 20.233954
A60: ='Pivot Tables'!A51 -> Holiday Promo - Email | B60: ='Pivot Tables'!B51 -> Email Marketing | C60: ='Pivot Tables'!C51 -> Lead Generation | D60: ='Pivot Tables'!D51 -> 330.47 | E60: ='Pivot Tables'!E51 -> 141818.1 | F60: ='Pivot Tables'!F51 -> 2355 | G60: ='Pivot Tables'!G51 -> 429.14062
... A63: ='Pivot Tables'!A54 -> New Customer Push - Google | B63: ='Pivot Tables'!B54 -> Google Search Ads | C63: ='Pivot Tables'!C54 -> Conversion | D63: ='Pivot Tables'!D54 -> 8688.3 | E63: ='Pivot Tables'!E54 -> 121892.52 | F63: ='Pivot Tables'!F54 -> 1308 | G63: ='Pivot Tables'!G54 -> 14.029502
